2021-03-26 09:51:14,248 ERROR: Exception on /user_profile/Daphne [GET] [in C:\Users\BlueberryCode\anaconda3\envs\flask38pycharm\lib\site-packages\flask\app.py:1891]
Traceback (most recent call last):
  File "C:\Users\BlueberryCode\anaconda3\envs\flask38pycharm\lib\site-packages\flask\app.py", line 2447, in wsgi_app
    response = self.full_dispatch_request()
  File "C:\Users\BlueberryCode\anaconda3\envs\flask38pycharm\lib\site-packages\flask\app.py", line 1952, in full_dispatch_request
    rv = self.handle_user_exception(e)
  File "C:\Users\BlueberryCode\anaconda3\envs\flask38pycharm\lib\site-packages\flask\app.py", line 1821, in handle_user_exception
    reraise(exc_type, exc_value, tb)
  File "C:\Users\BlueberryCode\anaconda3\envs\flask38pycharm\lib\site-packages\flask\_compat.py", line 39, in reraise
    raise value
  File "C:\Users\BlueberryCode\anaconda3\envs\flask38pycharm\lib\site-packages\flask\app.py", line 1950, in full_dispatch_request
    rv = self.dispatch_request()
  File "C:\Users\BlueberryCode\anaconda3\envs\flask38pycharm\lib\site-packages\flask\app.py", line 1936, in dispatch_request
    return self.view_functions[rule.endpoint](**req.view_args)
  File "C:\Users\BlueberryCode\anaconda3\envs\flask38pycharm\lib\site-packages\flask_login\utils.py", line 272, in decorated_view
    return func(*args, **kwargs)
  File "C:\Users\BlueberryCode\PycharmProjects\microblog\app\routes.py", line 135, in user_profile
    return render_template('profile.html', username=username, posts=posts.items,
  File "C:\Users\BlueberryCode\anaconda3\envs\flask38pycharm\lib\site-packages\flask\templating.py", line 137, in render_template
    return _render(
  File "C:\Users\BlueberryCode\anaconda3\envs\flask38pycharm\lib\site-packages\flask\templating.py", line 120, in _render
    rv = template.render(context)
  File "C:\Users\BlueberryCode\anaconda3\envs\flask38pycharm\lib\site-packages\jinja2\environment.py", line 1090, in render
    self.environment.handle_exception()
  File "C:\Users\BlueberryCode\anaconda3\envs\flask38pycharm\lib\site-packages\jinja2\environment.py", line 832, in handle_exception
    reraise(*rewrite_traceback_stack(source=source))
  File "C:\Users\BlueberryCode\anaconda3\envs\flask38pycharm\lib\site-packages\jinja2\_compat.py", line 28, in reraise
    raise value.with_traceback(tb)
  File "C:\Users\BlueberryCode\PycharmProjects\microblog\app\templates\profile.html", line 1, in top-level template code
    {% extends "base.html" %}
  File "C:\Users\BlueberryCode\PycharmProjects\microblog\app\templates\base.html", line 37, in top-level template code
    {% block content %}
  File "C:\Users\BlueberryCode\PycharmProjects\microblog\app\templates\profile.html", line 6, in block "content"
    <img src="{{ user.avatar(128) }}">
  File "C:\Users\BlueberryCode\anaconda3\envs\flask38pycharm\lib\site-packages\jinja2\environment.py", line 471, in getattr
    return getattr(obj, attribute)
jinja2.exceptions.UndefinedError: 'user' is undefined
2021-03-26 09:52:26,632 INFO: Microblog startup [in C:\Users\BlueberryCode\PycharmProjects\microblog\app\__init__.py:43]
2021-03-26 09:52:38,644 ERROR: Exception on /user_profile/Daphne [GET] [in C:\Users\BlueberryCode\anaconda3\envs\flask38pycharm\lib\site-packages\flask\app.py:1891]
Traceback (most recent call last):
  File "C:\Users\BlueberryCode\anaconda3\envs\flask38pycharm\lib\site-packages\flask\app.py", line 2447, in wsgi_app
    response = self.full_dispatch_request()
  File "C:\Users\BlueberryCode\anaconda3\envs\flask38pycharm\lib\site-packages\flask\app.py", line 1952, in full_dispatch_request
    rv = self.handle_user_exception(e)
  File "C:\Users\BlueberryCode\anaconda3\envs\flask38pycharm\lib\site-packages\flask\app.py", line 1821, in handle_user_exception
    reraise(exc_type, exc_value, tb)
  File "C:\Users\BlueberryCode\anaconda3\envs\flask38pycharm\lib\site-packages\flask\_compat.py", line 39, in reraise
    raise value
  File "C:\Users\BlueberryCode\anaconda3\envs\flask38pycharm\lib\site-packages\flask\app.py", line 1950, in full_dispatch_request
    rv = self.dispatch_request()
  File "C:\Users\BlueberryCode\anaconda3\envs\flask38pycharm\lib\site-packages\flask\app.py", line 1936, in dispatch_request
    return self.view_functions[rule.endpoint](**req.view_args)
  File "C:\Users\BlueberryCode\anaconda3\envs\flask38pycharm\lib\site-packages\flask_login\utils.py", line 272, in decorated_view
    return func(*args, **kwargs)
  File "C:\Users\BlueberryCode\PycharmProjects\microblog\app\routes.py", line 135, in user_profile
    return render_template('profile.html', username=username, posts=posts.items,
  File "C:\Users\BlueberryCode\anaconda3\envs\flask38pycharm\lib\site-packages\flask\templating.py", line 137, in render_template
    return _render(
  File "C:\Users\BlueberryCode\anaconda3\envs\flask38pycharm\lib\site-packages\flask\templating.py", line 120, in _render
    rv = template.render(context)
  File "C:\Users\BlueberryCode\anaconda3\envs\flask38pycharm\lib\site-packages\jinja2\environment.py", line 1090, in render
    self.environment.handle_exception()
  File "C:\Users\BlueberryCode\anaconda3\envs\flask38pycharm\lib\site-packages\jinja2\environment.py", line 832, in handle_exception
    reraise(*rewrite_traceback_stack(source=source))
  File "C:\Users\BlueberryCode\anaconda3\envs\flask38pycharm\lib\site-packages\jinja2\_compat.py", line 28, in reraise
    raise value.with_traceback(tb)
  File "C:\Users\BlueberryCode\PycharmProjects\microblog\app\templates\profile.html", line 1, in top-level template code
    {% extends "base.html" %}
  File "C:\Users\BlueberryCode\PycharmProjects\microblog\app\templates\base.html", line 37, in top-level template code
    {% block content %}
  File "C:\Users\BlueberryCode\PycharmProjects\microblog\app\templates\profile.html", line 6, in block "content"
    <img src="{{ user.avatar(128) }}">
  File "C:\Users\BlueberryCode\anaconda3\envs\flask38pycharm\lib\site-packages\jinja2\environment.py", line 471, in getattr
    return getattr(obj, attribute)
jinja2.exceptions.UndefinedError: 'user' is undefined
2021-03-26 09:54:23,982 INFO: Microblog startup [in C:\Users\BlueberryCode\PycharmProjects\microblog\app\__init__.py:43]
2021-03-26 09:54:37,308 ERROR: Exception on / [GET] [in C:\Users\BlueberryCode\anaconda3\envs\flask38pycharm\lib\site-packages\flask\app.py:1891]
Traceback (most recent call last):
  File "C:\Users\BlueberryCode\anaconda3\envs\flask38pycharm\lib\site-packages\flask\app.py", line 2447, in wsgi_app
    response = self.full_dispatch_request()
  File "C:\Users\BlueberryCode\anaconda3\envs\flask38pycharm\lib\site-packages\flask\app.py", line 1952, in full_dispatch_request
    rv = self.handle_user_exception(e)
  File "C:\Users\BlueberryCode\anaconda3\envs\flask38pycharm\lib\site-packages\flask\app.py", line 1821, in handle_user_exception
    reraise(exc_type, exc_value, tb)
  File "C:\Users\BlueberryCode\anaconda3\envs\flask38pycharm\lib\site-packages\flask\_compat.py", line 39, in reraise
    raise value
  File "C:\Users\BlueberryCode\anaconda3\envs\flask38pycharm\lib\site-packages\flask\app.py", line 1950, in full_dispatch_request
    rv = self.dispatch_request()
  File "C:\Users\BlueberryCode\anaconda3\envs\flask38pycharm\lib\site-packages\flask\app.py", line 1936, in dispatch_request
    return self.view_functions[rule.endpoint](**req.view_args)
  File "C:\Users\BlueberryCode\anaconda3\envs\flask38pycharm\lib\site-packages\flask_login\utils.py", line 272, in decorated_view
    return func(*args, **kwargs)
  File "C:\Users\BlueberryCode\PycharmProjects\microblog\app\routes.py", line 47, in index
    next_url, prev_url = check_prev_and_next_pages('index', posts)
  File "C:\Users\BlueberryCode\PycharmProjects\microblog\app\routes.py", line 13, in check_prev_and_next_pages
    next_url = url_for(webpage, page=posts.next_num, user=username.user)
AttributeError: 'NoneType' object has no attribute 'user'
2021-03-26 09:54:48,762 ERROR: Exception on /index [GET] [in C:\Users\BlueberryCode\anaconda3\envs\flask38pycharm\lib\site-packages\flask\app.py:1891]
Traceback (most recent call last):
  File "C:\Users\BlueberryCode\anaconda3\envs\flask38pycharm\lib\site-packages\flask\app.py", line 2447, in wsgi_app
    response = self.full_dispatch_request()
  File "C:\Users\BlueberryCode\anaconda3\envs\flask38pycharm\lib\site-packages\flask\app.py", line 1952, in full_dispatch_request
    rv = self.handle_user_exception(e)
  File "C:\Users\BlueberryCode\anaconda3\envs\flask38pycharm\lib\site-packages\flask\app.py", line 1821, in handle_user_exception
    reraise(exc_type, exc_value, tb)
  File "C:\Users\BlueberryCode\anaconda3\envs\flask38pycharm\lib\site-packages\flask\_compat.py", line 39, in reraise
    raise value
  File "C:\Users\BlueberryCode\anaconda3\envs\flask38pycharm\lib\site-packages\flask\app.py", line 1950, in full_dispatch_request
    rv = self.dispatch_request()
  File "C:\Users\BlueberryCode\anaconda3\envs\flask38pycharm\lib\site-packages\flask\app.py", line 1936, in dispatch_request
    return self.view_functions[rule.endpoint](**req.view_args)
  File "C:\Users\BlueberryCode\anaconda3\envs\flask38pycharm\lib\site-packages\flask_login\utils.py", line 272, in decorated_view
    return func(*args, **kwargs)
  File "C:\Users\BlueberryCode\PycharmProjects\microblog\app\routes.py", line 47, in index
    next_url, prev_url = check_prev_and_next_pages('index', posts)
  File "C:\Users\BlueberryCode\PycharmProjects\microblog\app\routes.py", line 13, in check_prev_and_next_pages
    next_url = url_for(webpage, page=posts.next_num, user=username.user)
AttributeError: 'NoneType' object has no attribute 'user'
2021-03-26 09:58:32,079 INFO: Microblog startup [in C:\Users\BlueberryCode\PycharmProjects\microblog\app\__init__.py:43]
2021-03-26 10:08:00,065 INFO: Microblog startup [in C:\Users\BlueberryCode\PycharmProjects\microblog\app\__init__.py:43]
