2021-03-25 15:02:05,808 ERROR: Exception on /explore [GET] [in C:\Users\BlueberryCode\anaconda3\envs\flask38pycharm\lib\site-packages\flask\app.py:1891]
Traceback (most recent call last):
  File "C:\Users\BlueberryCode\anaconda3\envs\flask38pycharm\lib\site-packages\flask\app.py", line 2447, in wsgi_app
    response = self.full_dispatch_request()
  File "C:\Users\BlueberryCode\anaconda3\envs\flask38pycharm\lib\site-packages\flask\app.py", line 1952, in full_dispatch_request
    rv = self.handle_user_exception(e)
  File "C:\Users\BlueberryCode\anaconda3\envs\flask38pycharm\lib\site-packages\flask\app.py", line 1821, in handle_user_exception
    reraise(exc_type, exc_value, tb)
  File "C:\Users\BlueberryCode\anaconda3\envs\flask38pycharm\lib\site-packages\flask\_compat.py", line 39, in reraise
    raise value
  File "C:\Users\BlueberryCode\anaconda3\envs\flask38pycharm\lib\site-packages\flask\app.py", line 1950, in full_dispatch_request
    rv = self.dispatch_request()
  File "C:\Users\BlueberryCode\anaconda3\envs\flask38pycharm\lib\site-packages\flask\app.py", line 1936, in dispatch_request
    return self.view_functions[rule.endpoint](**req.view_args)
  File "C:\Users\BlueberryCode\anaconda3\envs\flask38pycharm\lib\site-packages\flask_login\utils.py", line 272, in decorated_view
    return func(*args, **kwargs)
  File "C:\Users\BlueberryCode\PycharmProjects\microblog\app\routes.py", line 64, in explore
    return render_template('explore.html', title='Explore', posts=posts.items,
  File "C:\Users\BlueberryCode\anaconda3\envs\flask38pycharm\lib\site-packages\flask\templating.py", line 138, in render_template
    ctx.app.jinja_env.get_or_select_template(template_name_or_list),
  File "C:\Users\BlueberryCode\anaconda3\envs\flask38pycharm\lib\site-packages\jinja2\environment.py", line 930, in get_or_select_template
    return self.get_template(template_name_or_list, parent, globals)
  File "C:\Users\BlueberryCode\anaconda3\envs\flask38pycharm\lib\site-packages\jinja2\environment.py", line 883, in get_template
    return self._load_template(name, self.make_globals(globals))
  File "C:\Users\BlueberryCode\anaconda3\envs\flask38pycharm\lib\site-packages\jinja2\environment.py", line 857, in _load_template
    template = self.loader.load(self, name, globals)
  File "C:\Users\BlueberryCode\anaconda3\envs\flask38pycharm\lib\site-packages\jinja2\loaders.py", line 115, in load
    source, filename, uptodate = self.get_source(environment, name)
  File "C:\Users\BlueberryCode\anaconda3\envs\flask38pycharm\lib\site-packages\flask\templating.py", line 60, in get_source
    return self._get_source_fast(environment, template)
  File "C:\Users\BlueberryCode\anaconda3\envs\flask38pycharm\lib\site-packages\flask\templating.py", line 89, in _get_source_fast
    raise TemplateNotFound(template)
jinja2.exceptions.TemplateNotFound: explore.html
2021-03-25 15:05:47,041 INFO: Microblog startup [in C:\Users\BlueberryCode\PycharmProjects\microblog\app\__init__.py:43]
2021-03-25 15:12:41,549 INFO: Microblog startup [in C:\Users\BlueberryCode\PycharmProjects\microblog\app\__init__.py:43]
2021-03-25 15:17:41,369 INFO: Microblog startup [in C:\Users\BlueberryCode\PycharmProjects\microblog\app\__init__.py:43]
2021-03-25 15:18:50,074 INFO: Microblog startup [in C:\Users\BlueberryCode\PycharmProjects\microblog\app\__init__.py:43]
2021-03-25 15:22:07,561 INFO: Microblog startup [in C:\Users\BlueberryCode\PycharmProjects\microblog\app\__init__.py:43]
2021-03-25 15:22:27,344 ERROR: Exception on /user_profile/Daphne [GET] [in C:\Users\BlueberryCode\anaconda3\envs\flask38pycharm\lib\site-packages\flask\app.py:1891]
Traceback (most recent call last):
  File "C:\Users\BlueberryCode\anaconda3\envs\flask38pycharm\lib\site-packages\flask\app.py", line 2447, in wsgi_app
    response = self.full_dispatch_request()
  File "C:\Users\BlueberryCode\anaconda3\envs\flask38pycharm\lib\site-packages\flask\app.py", line 1952, in full_dispatch_request
    rv = self.handle_user_exception(e)
  File "C:\Users\BlueberryCode\anaconda3\envs\flask38pycharm\lib\site-packages\flask\app.py", line 1821, in handle_user_exception
    reraise(exc_type, exc_value, tb)
  File "C:\Users\BlueberryCode\anaconda3\envs\flask38pycharm\lib\site-packages\flask\_compat.py", line 39, in reraise
    raise value
  File "C:\Users\BlueberryCode\anaconda3\envs\flask38pycharm\lib\site-packages\flask\app.py", line 1950, in full_dispatch_request
    rv = self.dispatch_request()
  File "C:\Users\BlueberryCode\anaconda3\envs\flask38pycharm\lib\site-packages\flask\app.py", line 1936, in dispatch_request
    return self.view_functions[rule.endpoint](**req.view_args)
  File "C:\Users\BlueberryCode\anaconda3\envs\flask38pycharm\lib\site-packages\flask_login\utils.py", line 272, in decorated_view
    return func(*args, **kwargs)
  File "C:\Users\BlueberryCode\PycharmProjects\microblog\app\routes.py", line 132, in user_profile
    next_url, prev_url = check_prev_and_next_pages(posts)
TypeError: check_prev_and_next_pages() missing 1 required positional argument: 'posts'
2021-03-25 15:22:32,273 ERROR: Exception on /user_profile/Daphne [GET] [in C:\Users\BlueberryCode\anaconda3\envs\flask38pycharm\lib\site-packages\flask\app.py:1891]
Traceback (most recent call last):
  File "C:\Users\BlueberryCode\anaconda3\envs\flask38pycharm\lib\site-packages\flask\app.py", line 2447, in wsgi_app
    response = self.full_dispatch_request()
  File "C:\Users\BlueberryCode\anaconda3\envs\flask38pycharm\lib\site-packages\flask\app.py", line 1952, in full_dispatch_request
    rv = self.handle_user_exception(e)
  File "C:\Users\BlueberryCode\anaconda3\envs\flask38pycharm\lib\site-packages\flask\app.py", line 1821, in handle_user_exception
    reraise(exc_type, exc_value, tb)
  File "C:\Users\BlueberryCode\anaconda3\envs\flask38pycharm\lib\site-packages\flask\_compat.py", line 39, in reraise
    raise value
  File "C:\Users\BlueberryCode\anaconda3\envs\flask38pycharm\lib\site-packages\flask\app.py", line 1950, in full_dispatch_request
    rv = self.dispatch_request()
  File "C:\Users\BlueberryCode\anaconda3\envs\flask38pycharm\lib\site-packages\flask\app.py", line 1936, in dispatch_request
    return self.view_functions[rule.endpoint](**req.view_args)
  File "C:\Users\BlueberryCode\anaconda3\envs\flask38pycharm\lib\site-packages\flask_login\utils.py", line 272, in decorated_view
    return func(*args, **kwargs)
  File "C:\Users\BlueberryCode\PycharmProjects\microblog\app\routes.py", line 132, in user_profile
    next_url, prev_url = check_prev_and_next_pages(posts)
TypeError: check_prev_and_next_pages() missing 1 required positional argument: 'posts'
2021-03-25 15:24:00,901 INFO: Microblog startup [in C:\Users\BlueberryCode\PycharmProjects\microblog\app\__init__.py:43]
2021-03-25 15:25:16,766 ERROR: Exception on /user_profile/Daphne [GET] [in C:\Users\BlueberryCode\anaconda3\envs\flask38pycharm\lib\site-packages\flask\app.py:1891]
Traceback (most recent call last):
  File "C:\Users\BlueberryCode\anaconda3\envs\flask38pycharm\lib\site-packages\flask\app.py", line 2447, in wsgi_app
    response = self.full_dispatch_request()
  File "C:\Users\BlueberryCode\anaconda3\envs\flask38pycharm\lib\site-packages\flask\app.py", line 1952, in full_dispatch_request
    rv = self.handle_user_exception(e)
  File "C:\Users\BlueberryCode\anaconda3\envs\flask38pycharm\lib\site-packages\flask\app.py", line 1821, in handle_user_exception
    reraise(exc_type, exc_value, tb)
  File "C:\Users\BlueberryCode\anaconda3\envs\flask38pycharm\lib\site-packages\flask\_compat.py", line 39, in reraise
    raise value
  File "C:\Users\BlueberryCode\anaconda3\envs\flask38pycharm\lib\site-packages\flask\app.py", line 1950, in full_dispatch_request
    rv = self.dispatch_request()
  File "C:\Users\BlueberryCode\anaconda3\envs\flask38pycharm\lib\site-packages\flask\app.py", line 1936, in dispatch_request
    return self.view_functions[rule.endpoint](**req.view_args)
  File "C:\Users\BlueberryCode\anaconda3\envs\flask38pycharm\lib\site-packages\flask_login\utils.py", line 272, in decorated_view
    return func(*args, **kwargs)
  File "C:\Users\BlueberryCode\PycharmProjects\microblog\app\routes.py", line 132, in user_profile
    next_url, prev_url = check_prev_and_next_pages('user_profile', posts)
  File "C:\Users\BlueberryCode\PycharmProjects\microblog\app\routes.py", line 13, in check_prev_and_next_pages
    next_url = url_for(webpage, page=posts.next_num)
  File "C:\Users\BlueberryCode\anaconda3\envs\flask38pycharm\lib\site-packages\flask\helpers.py", line 370, in url_for
    return appctx.app.handle_url_build_error(error, endpoint, values)
  File "C:\Users\BlueberryCode\anaconda3\envs\flask38pycharm\lib\site-packages\flask\app.py", line 2216, in handle_url_build_error
    reraise(exc_type, exc_value, tb)
  File "C:\Users\BlueberryCode\anaconda3\envs\flask38pycharm\lib\site-packages\flask\_compat.py", line 39, in reraise
    raise value
  File "C:\Users\BlueberryCode\anaconda3\envs\flask38pycharm\lib\site-packages\flask\helpers.py", line 357, in url_for
    rv = url_adapter.build(
  File "C:\Users\BlueberryCode\anaconda3\envs\flask38pycharm\lib\site-packages\werkzeug\routing.py", line 2179, in build
    raise BuildError(endpoint, values, method, self)
werkzeug.routing.BuildError: Could not build url for endpoint 'user_profile' with values ['page']. Did you forget to specify values ['username']?
