2021-03-24 18:10:23,823 ERROR: Exception on /unfollow/louis [POST] [in C:\Users\BlueberryCode\anaconda3\envs\flask38pycharm\lib\site-packages\flask\app.py:1891]
Traceback (most recent call last):
  File "C:\Users\BlueberryCode\anaconda3\envs\flask38pycharm\lib\site-packages\flask\app.py", line 2447, in wsgi_app
    response = self.full_dispatch_request()
  File "C:\Users\BlueberryCode\anaconda3\envs\flask38pycharm\lib\site-packages\flask\app.py", line 1952, in full_dispatch_request
    rv = self.handle_user_exception(e)
  File "C:\Users\BlueberryCode\anaconda3\envs\flask38pycharm\lib\site-packages\flask\app.py", line 1821, in handle_user_exception
    reraise(exc_type, exc_value, tb)
  File "C:\Users\BlueberryCode\anaconda3\envs\flask38pycharm\lib\site-packages\flask\_compat.py", line 39, in reraise
    raise value
  File "C:\Users\BlueberryCode\anaconda3\envs\flask38pycharm\lib\site-packages\flask\app.py", line 1950, in full_dispatch_request
    rv = self.dispatch_request()
  File "C:\Users\BlueberryCode\anaconda3\envs\flask38pycharm\lib\site-packages\flask\app.py", line 1936, in dispatch_request
    return self.view_functions[rule.endpoint](**req.view_args)
  File "C:\Users\BlueberryCode\anaconda3\envs\flask38pycharm\lib\site-packages\flask_login\utils.py", line 272, in decorated_view
    return func(*args, **kwargs)
  File "C:\Users\BlueberryCode\PycharmProjects\microblog\app\routes.py", line 166, in unfollow
    return redirect(url_for('user', username=username))
  File "C:\Users\BlueberryCode\anaconda3\envs\flask38pycharm\lib\site-packages\flask\helpers.py", line 370, in url_for
    return appctx.app.handle_url_build_error(error, endpoint, values)
  File "C:\Users\BlueberryCode\anaconda3\envs\flask38pycharm\lib\site-packages\flask\app.py", line 2216, in handle_url_build_error
    reraise(exc_type, exc_value, tb)
  File "C:\Users\BlueberryCode\anaconda3\envs\flask38pycharm\lib\site-packages\flask\_compat.py", line 39, in reraise
    raise value
  File "C:\Users\BlueberryCode\anaconda3\envs\flask38pycharm\lib\site-packages\flask\helpers.py", line 357, in url_for
    rv = url_adapter.build(
  File "C:\Users\BlueberryCode\anaconda3\envs\flask38pycharm\lib\site-packages\werkzeug\routing.py", line 2179, in build
    raise BuildError(endpoint, values, method, self)
werkzeug.routing.BuildError: Could not build url for endpoint 'user' with values ['username']. Did you mean 'user_profile' instead?
2021-03-24 18:10:35,673 ERROR: Exception on /follow/louis [POST] [in C:\Users\BlueberryCode\anaconda3\envs\flask38pycharm\lib\site-packages\flask\app.py:1891]
Traceback (most recent call last):
  File "C:\Users\BlueberryCode\anaconda3\envs\flask38pycharm\lib\site-packages\flask\app.py", line 2447, in wsgi_app
    response = self.full_dispatch_request()
  File "C:\Users\BlueberryCode\anaconda3\envs\flask38pycharm\lib\site-packages\flask\app.py", line 1952, in full_dispatch_request
    rv = self.handle_user_exception(e)
  File "C:\Users\BlueberryCode\anaconda3\envs\flask38pycharm\lib\site-packages\flask\app.py", line 1821, in handle_user_exception
    reraise(exc_type, exc_value, tb)
  File "C:\Users\BlueberryCode\anaconda3\envs\flask38pycharm\lib\site-packages\flask\_compat.py", line 39, in reraise
    raise value
  File "C:\Users\BlueberryCode\anaconda3\envs\flask38pycharm\lib\site-packages\flask\app.py", line 1950, in full_dispatch_request
    rv = self.dispatch_request()
  File "C:\Users\BlueberryCode\anaconda3\envs\flask38pycharm\lib\site-packages\flask\app.py", line 1936, in dispatch_request
    return self.view_functions[rule.endpoint](**req.view_args)
  File "C:\Users\BlueberryCode\anaconda3\envs\flask38pycharm\lib\site-packages\flask_login\utils.py", line 272, in decorated_view
    return func(*args, **kwargs)
  File "C:\Users\BlueberryCode\PycharmProjects\microblog\app\routes.py", line 146, in follow
    return redirect(url_for('user', username=username))
  File "C:\Users\BlueberryCode\anaconda3\envs\flask38pycharm\lib\site-packages\flask\helpers.py", line 370, in url_for
    return appctx.app.handle_url_build_error(error, endpoint, values)
  File "C:\Users\BlueberryCode\anaconda3\envs\flask38pycharm\lib\site-packages\flask\app.py", line 2216, in handle_url_build_error
    reraise(exc_type, exc_value, tb)
  File "C:\Users\BlueberryCode\anaconda3\envs\flask38pycharm\lib\site-packages\flask\_compat.py", line 39, in reraise
    raise value
  File "C:\Users\BlueberryCode\anaconda3\envs\flask38pycharm\lib\site-packages\flask\helpers.py", line 357, in url_for
    rv = url_adapter.build(
  File "C:\Users\BlueberryCode\anaconda3\envs\flask38pycharm\lib\site-packages\werkzeug\routing.py", line 2179, in build
    raise BuildError(endpoint, values, method, self)
werkzeug.routing.BuildError: Could not build url for endpoint 'user' with values ['username']. Did you mean 'user_profile' instead?
2021-03-24 18:10:54,131 ERROR: Exception on /follow/philippe [POST] [in C:\Users\BlueberryCode\anaconda3\envs\flask38pycharm\lib\site-packages\flask\app.py:1891]
Traceback (most recent call last):
  File "C:\Users\BlueberryCode\anaconda3\envs\flask38pycharm\lib\site-packages\flask\app.py", line 2447, in wsgi_app
    response = self.full_dispatch_request()
  File "C:\Users\BlueberryCode\anaconda3\envs\flask38pycharm\lib\site-packages\flask\app.py", line 1952, in full_dispatch_request
    rv = self.handle_user_exception(e)
  File "C:\Users\BlueberryCode\anaconda3\envs\flask38pycharm\lib\site-packages\flask\app.py", line 1821, in handle_user_exception
    reraise(exc_type, exc_value, tb)
  File "C:\Users\BlueberryCode\anaconda3\envs\flask38pycharm\lib\site-packages\flask\_compat.py", line 39, in reraise
    raise value
  File "C:\Users\BlueberryCode\anaconda3\envs\flask38pycharm\lib\site-packages\flask\app.py", line 1950, in full_dispatch_request
    rv = self.dispatch_request()
  File "C:\Users\BlueberryCode\anaconda3\envs\flask38pycharm\lib\site-packages\flask\app.py", line 1936, in dispatch_request
    return self.view_functions[rule.endpoint](**req.view_args)
  File "C:\Users\BlueberryCode\anaconda3\envs\flask38pycharm\lib\site-packages\flask_login\utils.py", line 272, in decorated_view
    return func(*args, **kwargs)
  File "C:\Users\BlueberryCode\PycharmProjects\microblog\app\routes.py", line 146, in follow
    return redirect(url_for('user', username=username))
  File "C:\Users\BlueberryCode\anaconda3\envs\flask38pycharm\lib\site-packages\flask\helpers.py", line 370, in url_for
    return appctx.app.handle_url_build_error(error, endpoint, values)
  File "C:\Users\BlueberryCode\anaconda3\envs\flask38pycharm\lib\site-packages\flask\app.py", line 2216, in handle_url_build_error
    reraise(exc_type, exc_value, tb)
  File "C:\Users\BlueberryCode\anaconda3\envs\flask38pycharm\lib\site-packages\flask\_compat.py", line 39, in reraise
    raise value
  File "C:\Users\BlueberryCode\anaconda3\envs\flask38pycharm\lib\site-packages\flask\helpers.py", line 357, in url_for
    rv = url_adapter.build(
  File "C:\Users\BlueberryCode\anaconda3\envs\flask38pycharm\lib\site-packages\werkzeug\routing.py", line 2179, in build
    raise BuildError(endpoint, values, method, self)
werkzeug.routing.BuildError: Could not build url for endpoint 'user' with values ['username']. Did you mean 'user_profile' instead?
2021-03-24 18:13:07,805 INFO: Microblog startup [in C:\Users\BlueberryCode\PycharmProjects\microblog\app\__init__.py:43]
2021-03-24 18:13:55,671 ERROR: Exception on /unfollow/philippe [POST] [in C:\Users\BlueberryCode\anaconda3\envs\flask38pycharm\lib\site-packages\flask\app.py:1891]
Traceback (most recent call last):
  File "C:\Users\BlueberryCode\anaconda3\envs\flask38pycharm\lib\site-packages\flask\app.py", line 2447, in wsgi_app
    response = self.full_dispatch_request()
  File "C:\Users\BlueberryCode\anaconda3\envs\flask38pycharm\lib\site-packages\flask\app.py", line 1952, in full_dispatch_request
    rv = self.handle_user_exception(e)
  File "C:\Users\BlueberryCode\anaconda3\envs\flask38pycharm\lib\site-packages\flask\app.py", line 1821, in handle_user_exception
    reraise(exc_type, exc_value, tb)
  File "C:\Users\BlueberryCode\anaconda3\envs\flask38pycharm\lib\site-packages\flask\_compat.py", line 39, in reraise
    raise value
  File "C:\Users\BlueberryCode\anaconda3\envs\flask38pycharm\lib\site-packages\flask\app.py", line 1950, in full_dispatch_request
    rv = self.dispatch_request()
  File "C:\Users\BlueberryCode\anaconda3\envs\flask38pycharm\lib\site-packages\flask\app.py", line 1936, in dispatch_request
    return self.view_functions[rule.endpoint](**req.view_args)
  File "C:\Users\BlueberryCode\anaconda3\envs\flask38pycharm\lib\site-packages\flask_login\utils.py", line 272, in decorated_view
    return func(*args, **kwargs)
  File "C:\Users\BlueberryCode\PycharmProjects\microblog\app\routes.py", line 166, in unfollow
    return redirect(url_for('user', username=username))
  File "C:\Users\BlueberryCode\anaconda3\envs\flask38pycharm\lib\site-packages\flask\helpers.py", line 370, in url_for
    return appctx.app.handle_url_build_error(error, endpoint, values)
  File "C:\Users\BlueberryCode\anaconda3\envs\flask38pycharm\lib\site-packages\flask\app.py", line 2216, in handle_url_build_error
    reraise(exc_type, exc_value, tb)
  File "C:\Users\BlueberryCode\anaconda3\envs\flask38pycharm\lib\site-packages\flask\_compat.py", line 39, in reraise
    raise value
  File "C:\Users\BlueberryCode\anaconda3\envs\flask38pycharm\lib\site-packages\flask\helpers.py", line 357, in url_for
    rv = url_adapter.build(
  File "C:\Users\BlueberryCode\anaconda3\envs\flask38pycharm\lib\site-packages\werkzeug\routing.py", line 2179, in build
    raise BuildError(endpoint, values, method, self)
werkzeug.routing.BuildError: Could not build url for endpoint 'user' with values ['username']. Did you mean 'user_profile' instead?
2021-03-24 18:15:26,468 INFO: Microblog startup [in C:\Users\BlueberryCode\PycharmProjects\microblog\app\__init__.py:43]
2021-03-25 08:51:57,492 INFO: Microblog startup [in C:\Users\BlueberryCode\PycharmProjects\microblog\app\__init__.py:43]
