2021-03-25 15:25:21,545 ERROR: Exception on /user_profile/Daphne [GET] [in C:\Users\BlueberryCode\anaconda3\envs\flask38pycharm\lib\site-packages\flask\app.py:1891]
Traceback (most recent call last):
  File "C:\Users\BlueberryCode\anaconda3\envs\flask38pycharm\lib\site-packages\flask\app.py", line 2447, in wsgi_app
    response = self.full_dispatch_request()
  File "C:\Users\BlueberryCode\anaconda3\envs\flask38pycharm\lib\site-packages\flask\app.py", line 1952, in full_dispatch_request
    rv = self.handle_user_exception(e)
  File "C:\Users\BlueberryCode\anaconda3\envs\flask38pycharm\lib\site-packages\flask\app.py", line 1821, in handle_user_exception
    reraise(exc_type, exc_value, tb)
  File "C:\Users\BlueberryCode\anaconda3\envs\flask38pycharm\lib\site-packages\flask\_compat.py", line 39, in reraise
    raise value
  File "C:\Users\BlueberryCode\anaconda3\envs\flask38pycharm\lib\site-packages\flask\app.py", line 1950, in full_dispatch_request
    rv = self.dispatch_request()
  File "C:\Users\BlueberryCode\anaconda3\envs\flask38pycharm\lib\site-packages\flask\app.py", line 1936, in dispatch_request
    return self.view_functions[rule.endpoint](**req.view_args)
  File "C:\Users\BlueberryCode\anaconda3\envs\flask38pycharm\lib\site-packages\flask_login\utils.py", line 272, in decorated_view
    return func(*args, **kwargs)
  File "C:\Users\BlueberryCode\PycharmProjects\microblog\app\routes.py", line 132, in user_profile
    next_url, prev_url = check_prev_and_next_pages('user_profile', posts)
  File "C:\Users\BlueberryCode\PycharmProjects\microblog\app\routes.py", line 13, in check_prev_and_next_pages
    next_url = url_for(webpage, page=posts.next_num)
  File "C:\Users\BlueberryCode\anaconda3\envs\flask38pycharm\lib\site-packages\flask\helpers.py", line 370, in url_for
    return appctx.app.handle_url_build_error(error, endpoint, values)
  File "C:\Users\BlueberryCode\anaconda3\envs\flask38pycharm\lib\site-packages\flask\app.py", line 2216, in handle_url_build_error
    reraise(exc_type, exc_value, tb)
  File "C:\Users\BlueberryCode\anaconda3\envs\flask38pycharm\lib\site-packages\flask\_compat.py", line 39, in reraise
    raise value
  File "C:\Users\BlueberryCode\anaconda3\envs\flask38pycharm\lib\site-packages\flask\helpers.py", line 357, in url_for
    rv = url_adapter.build(
  File "C:\Users\BlueberryCode\anaconda3\envs\flask38pycharm\lib\site-packages\werkzeug\routing.py", line 2179, in build
    raise BuildError(endpoint, values, method, self)
werkzeug.routing.BuildError: Could not build url for endpoint 'user_profile' with values ['page']. Did you forget to specify values ['username']?
2021-03-25 15:25:40,420 ERROR: Exception on /user_profile/Daphne [GET] [in C:\Users\BlueberryCode\anaconda3\envs\flask38pycharm\lib\site-packages\flask\app.py:1891]
Traceback (most recent call last):
  File "C:\Users\BlueberryCode\anaconda3\envs\flask38pycharm\lib\site-packages\flask\app.py", line 2447, in wsgi_app
    response = self.full_dispatch_request()
  File "C:\Users\BlueberryCode\anaconda3\envs\flask38pycharm\lib\site-packages\flask\app.py", line 1952, in full_dispatch_request
    rv = self.handle_user_exception(e)
  File "C:\Users\BlueberryCode\anaconda3\envs\flask38pycharm\lib\site-packages\flask\app.py", line 1821, in handle_user_exception
    reraise(exc_type, exc_value, tb)
  File "C:\Users\BlueberryCode\anaconda3\envs\flask38pycharm\lib\site-packages\flask\_compat.py", line 39, in reraise
    raise value
  File "C:\Users\BlueberryCode\anaconda3\envs\flask38pycharm\lib\site-packages\flask\app.py", line 1950, in full_dispatch_request
    rv = self.dispatch_request()
  File "C:\Users\BlueberryCode\anaconda3\envs\flask38pycharm\lib\site-packages\flask\app.py", line 1936, in dispatch_request
    return self.view_functions[rule.endpoint](**req.view_args)
  File "C:\Users\BlueberryCode\anaconda3\envs\flask38pycharm\lib\site-packages\flask_login\utils.py", line 272, in decorated_view
    return func(*args, **kwargs)
  File "C:\Users\BlueberryCode\PycharmProjects\microblog\app\routes.py", line 132, in user_profile
    next_url, prev_url = check_prev_and_next_pages('user_profile', posts)
  File "C:\Users\BlueberryCode\PycharmProjects\microblog\app\routes.py", line 13, in check_prev_and_next_pages
    next_url = url_for(webpage, page=posts.next_num)
  File "C:\Users\BlueberryCode\anaconda3\envs\flask38pycharm\lib\site-packages\flask\helpers.py", line 370, in url_for
    return appctx.app.handle_url_build_error(error, endpoint, values)
  File "C:\Users\BlueberryCode\anaconda3\envs\flask38pycharm\lib\site-packages\flask\app.py", line 2216, in handle_url_build_error
    reraise(exc_type, exc_value, tb)
  File "C:\Users\BlueberryCode\anaconda3\envs\flask38pycharm\lib\site-packages\flask\_compat.py", line 39, in reraise
    raise value
  File "C:\Users\BlueberryCode\anaconda3\envs\flask38pycharm\lib\site-packages\flask\helpers.py", line 357, in url_for
    rv = url_adapter.build(
  File "C:\Users\BlueberryCode\anaconda3\envs\flask38pycharm\lib\site-packages\werkzeug\routing.py", line 2179, in build
    raise BuildError(endpoint, values, method, self)
werkzeug.routing.BuildError: Could not build url for endpoint 'user_profile' with values ['page']. Did you forget to specify values ['username']?
2021-03-25 15:29:32,924 INFO: Microblog startup [in C:\Users\BlueberryCode\PycharmProjects\microblog\app\__init__.py:43]
2021-03-25 15:29:47,952 ERROR: Exception on /user_profile/Daphne [GET] [in C:\Users\BlueberryCode\anaconda3\envs\flask38pycharm\lib\site-packages\flask\app.py:1891]
Traceback (most recent call last):
  File "C:\Users\BlueberryCode\anaconda3\envs\flask38pycharm\lib\site-packages\flask\app.py", line 2447, in wsgi_app
    response = self.full_dispatch_request()
  File "C:\Users\BlueberryCode\anaconda3\envs\flask38pycharm\lib\site-packages\flask\app.py", line 1952, in full_dispatch_request
    rv = self.handle_user_exception(e)
  File "C:\Users\BlueberryCode\anaconda3\envs\flask38pycharm\lib\site-packages\flask\app.py", line 1821, in handle_user_exception
    reraise(exc_type, exc_value, tb)
  File "C:\Users\BlueberryCode\anaconda3\envs\flask38pycharm\lib\site-packages\flask\_compat.py", line 39, in reraise
    raise value
  File "C:\Users\BlueberryCode\anaconda3\envs\flask38pycharm\lib\site-packages\flask\app.py", line 1950, in full_dispatch_request
    rv = self.dispatch_request()
  File "C:\Users\BlueberryCode\anaconda3\envs\flask38pycharm\lib\site-packages\flask\app.py", line 1936, in dispatch_request
    return self.view_functions[rule.endpoint](**req.view_args)
  File "C:\Users\BlueberryCode\anaconda3\envs\flask38pycharm\lib\site-packages\flask_login\utils.py", line 272, in decorated_view
    return func(*args, **kwargs)
  File "C:\Users\BlueberryCode\PycharmProjects\microblog\app\routes.py", line 132, in user_profile
    next_url, prev_url = check_prev_and_next_pages('user_profile', posts)
  File "C:\Users\BlueberryCode\PycharmProjects\microblog\app\routes.py", line 13, in check_prev_and_next_pages
    next_url = url_for(webpage, page=posts.next_num)
  File "C:\Users\BlueberryCode\anaconda3\envs\flask38pycharm\lib\site-packages\flask\helpers.py", line 370, in url_for
    return appctx.app.handle_url_build_error(error, endpoint, values)
  File "C:\Users\BlueberryCode\anaconda3\envs\flask38pycharm\lib\site-packages\flask\app.py", line 2216, in handle_url_build_error
    reraise(exc_type, exc_value, tb)
  File "C:\Users\BlueberryCode\anaconda3\envs\flask38pycharm\lib\site-packages\flask\_compat.py", line 39, in reraise
    raise value
  File "C:\Users\BlueberryCode\anaconda3\envs\flask38pycharm\lib\site-packages\flask\helpers.py", line 357, in url_for
    rv = url_adapter.build(
  File "C:\Users\BlueberryCode\anaconda3\envs\flask38pycharm\lib\site-packages\werkzeug\routing.py", line 2179, in build
    raise BuildError(endpoint, values, method, self)
werkzeug.routing.BuildError: Could not build url for endpoint 'user_profile' with values ['page']. Did you forget to specify values ['username']?
